Workbook

Sheet Resumen
B2: MIGRACIÓN BACKEND — SEGUIMIENTO GLOBAL DE ACTIVIDADES
B3: Proyectos: Core_Surgir | Onboarding | Web Surgir · Capas: Integración + Backend · Total APIs: 35 | Total actividades por API: 25
B6: TOTAL APIs | C6: ACTIVIDADES TOTALES | D6: ACTVS. COMPLETADAS | E6: % AVANCE GLOBAL | F6: PEND. DEPLOY DEV | G6: META | H6: NODE/JAVA VERSIONES | I6: SONAR PENDIENTE
B7: =C16 -> 35 | C7: =D16 -> 875 | D7: =E16 -> 813 | E7: =E16/D16 -> 0.92914286 | F7: =C16-F43 -> 5 | G7: Abr 2026 | H7: 24 / 21 | I7: =C16-F32 -> 0
B8: 12 Integ. + 16 Back. + 7 Orq. | C8: 24 act. x 35 APIs | D8: de 840 actividades | E8: todas las actividades | F8: Ningún API desplegado aún | G8: Go Live adelantado | H8: NodeJS 24 + Java 21 | I8: Todas las APIs pendiente
B11: RESUMEN POR CAPA — Progreso de actividades completadas
B12: Capa | C12: APIs | D12: Act. Totales | E12: Completadas | F12: En Curso | G12: Pendientes | H12: % Avance | I12: Deploy DEV
B13: Integración | C13: ='Capa API'!A16 -> 12 | D13: =C13*COUNTIF(' Capa Integración'!H4:AF4, "*") -> 300 | E13: =COUNTIF(' Capa Integración'!H5:AF16,"Completado") -> 288 | F13: =D13-(E13+G13) -> 0 | G13: =COUNTIF(' Capa Integración'!H5:AF16,"Pendiente") -> 12 | H13: =E13/D13 -> 0.96 | I13: Pendiente
B14: API | C14: ='Capa API'!A20 -> 16 | D14: =C14*COUNTIF('Capa API'!H4:AF4, "*") -> 400 | E14: =COUNTIF('Capa API'!H5:AF20,"Completado") -> 366 | F14: =D14-(E14+G14) -> 20 | G14: =COUNTIF('Capa API'!H5:AF20,"Pendiente") -> 14 | H14: =E14/D14 -> 0.915 | I14: Pendiente
B15: Orquestación | C15: ='Capa Orquestación'!A11 -> 7 | D15: =C15*COUNTIF('Capa Orquestación'!H4:AF4, "*") -> 175 | E15: =COUNTIF('Capa Orquestación'!H5:AF11,"Completado") -> 159 | F15: =D15-(E15+G15) -> 3 | G15: =COUNTIF('Capa Orquestación'!H5:AF11,"Pendiente") -> 13 | H15: =E15/D15 -> 0.90857143 | I15: Pendiente
B16: TOTAL GENERAL | C16: =SUM(C13:C15) -> 35 | D16: =SUM(D13:D15) -> 875 | E16: =SUM(E13:E15) -> 813 | F16: =SUM(F13:F15) -> 23 | G16: =SUM(G13:G15) -> 39 | H16: =SUM(H13:H15)/3 -> 0.92785714 | I16: Pendiente
B19: PROGRESO POR ACTIVIDAD — % de APIs con la tarea completada (capa integración + capa backend)
B20: Actividad | C20: Completadas (Integ.) | D20: Completadas (Back.) | E20: Completadas (Orq.) | F20: Total Complet. | G20: % APIs Completadas | H20: Estado global
B21: Creación de componente Gluon | C21: =COUNTIF(' Capa Integración'!H5:H16,"Completado") -> 12 | D21: =COUNTIF('Capa API'!H5:H20,"Completado") -> 16 | E21: =COUNTIF('Capa Orquestación'!H5:H11,"Completado") -> 7 | F21: =SUM(C21:E21) -> 35 | G21: =F21/C$16 -> 1 | H21: Completado
B22: Migrar versión Java 11 a 21 | C22: =COUNTIF(' Capa Integración'!I5:I16,"Completado") -> 12 | D22: =COUNTIF('Capa API'!I5:I20,"Completado") -> 16 | E22: =COUNTIF('Capa Orquestación'!I5:I11,"Completado") -> 7 | F22: =SUM(C22:E22) -> 35 | G22: =F22/C$16 -> 1 | H22: Completado
B23: Migrar SQL hacia Postgres | C23: =COUNTIF(' Capa Integración'!J5:J16,"Completado") -> 12 | D23: =COUNTIF('Capa API'!J5:J20,"Completado") -> 16 | E23: =COUNTIF('Capa Orquestación'!J5:J11,"Completado") -> 7 | F23: =SUM(C23:E23) -> 35 | G23: =F23/C$16 -> 1 | H23: Completado
B24: Implementación de arquitectura Gluon | C24: =COUNTIF(' Capa Integración'!K5:K16,"Completado") -> 12 | D24: =COUNTIF('Capa API'!K5:K20,"Completado") -> 16 | E24: =COUNTIF('Capa Orquestación'!K5:K11,"Completado") -> 7 | F24: =SUM(C24:E24) -> 35 | G24: =F24/C$16 -> 1 | H24: Completado
B25: Secuencia de deployment con YMLs | C25: =COUNTIF(' Capa Integración'!L5:L16,"Completado") -> 12 | D25: =COUNTIF('Capa API'!L5:L20,"Completado") -> 16 | E25: =COUNTIF('Capa Orquestación'!L5:L11,"Completado") -> 7 | F25: =SUM(C25:E25) -> 35 | G25: =F25/C$16 -> 1 | H25: Completado
B26: Generación Swagger de API (.yml) | C26: =COUNTIF(' Capa Integración'!M5:M16,"Completado") -> 12 | D26: =COUNTIF('Capa API'!M5:M20,"Completado") -> 16 | E26: =COUNTIF('Capa Orquestación'!M5:M11,"Completado") -> 7 | F26: =SUM(C26:E26) -> 35 | G26: =F26/C$16 -> 1 | H26: Completado
B27: Levantar API (build and dev) | C27: =COUNTIF(' Capa Integración'!N5:N16,"Completado") -> 12 | D27: =COUNTIF('Capa API'!N5:N20,"Completado") -> 16 | E27: =COUNTIF('Capa Orquestación'!N5:N11,"Completado") -> 7 | F27: =SUM(C27:E27) -> 35 | G27: =F27/C$16 -> 1 | H27: Completado
B28: Validar endpoints | C28: =COUNTIF(' Capa Integración'!O5:O16,"Completado") -> 12 | D28: =COUNTIF('Capa API'!O5:O20,"Completado") -> 16 | E28: =COUNTIF('Capa Orquestación'!O5:O11,"Completado") -> 7 | F28: =SUM(C28:E28) -> 35 | G28: =F28/C$16 -> 1 | H28: Completado
B29: Unit Tests (UTs) | C29: =COUNTIF(' Capa Integración'!P5:P16,"Completado") -> 12 | D29: =COUNTIF('Capa API'!P5:P20,"Completado") -> 16 | E29: =COUNTIF('Capa Orquestación'!P5:P11,"Completado") -> 7 | F29: =SUM(C29:E29) -> 35 | G29: =F29/C$16 -> 1 | H29: Completado
B30: Subir cambios a GitHub y Azure | C30: =COUNTIF(' Capa Integración'!Q5:Q16,"Completado") -> 12 | D30: =COUNTIF('Capa API'!Q5:Q20,"Completado") -> 16 | E30: =COUNTIF('Capa Orquestación'!Q5:Q11,"Completado") -> 7 | F30: =SUM(C30:E30) -> 35 | G30: =F30/C$16 -> 1 | H30: Completado
B31: Generar PRs a deployment y dev | C31: =COUNTIF(' Capa Integración'!R5:R16,"Completado") -> 12 | D31: =COUNTIF('Capa API'!R5:R20,"Completado") -> 16 | E31: =COUNTIF('Capa Orquestación'!R5:R11,"Completado") -> 7 | F31: =SUM(C31:E31) -> 35 | G31: =F31/C$16 -> 1 | H31: Completado
B32: Configurar SonarQube / Vulnerabilidades | C32: =COUNTIF(' Capa Integración'!S5:S16,"Completado") -> 12 | D32: =COUNTIF('Capa API'!S5:S20,"Completado") -> 16 | E32: =COUNTIF('Capa Orquestación'!S5:S11,"Completado") -> 7 | F32: =SUM(C32:E32) -> 35 | G32: =F32/C$16 -> 1 | H32: Completado
B33: Instalación de node24 en laptop | C33: =COUNTIF(' Capa Integración'!T5:T16,"Completado") -> 12 | D33: =COUNTIF('Capa API'!T5:T20,"Completado") -> 16 | E33: =COUNTIF('Capa Orquestación'!T5:T11,"Completado") -> 7 | F33: =SUM(C33:E33) -> 35 | G33: =F33/C$16 -> 1 | H33: Completado
B34: Distributed Tracing (App Insights) | C34: =COUNTIF(' Capa Integración'!U5:U16,"Completado") -> 12 | D34: =COUNTIF('Capa API'!U5:U20,"Completado") -> 16 | E34: =COUNTIF('Capa Orquestación'!U5:U11,"Completado") -> 7 | F34: =SUM(C34:E34) -> 35 | G34: =F34/C$16 -> 1 | H34: Completado
B35: Propagación de nuevos headers | C35: =COUNTIF(' Capa Integración'!V5:V16,"Completado") -> 12 | D35: =COUNTIF('Capa API'!V5:V20,"Completado") -> 16 | E35: =COUNTIF('Capa Orquestación'!V5:V11,"Completado") -> 7 | F35: =SUM(C35:E35) -> 35 | G35: =F35/C$16 -> 1 | H35: Completado
B36: Validación de headers | C36: =COUNTIF(' Capa Integración'!W5:W16,"Completado") -> 12 | D36: =COUNTIF('Capa API'!W5:W20,"Completado") -> 16 | E36: =COUNTIF('Capa Orquestación'!W5:W11,"Completado") -> 7 | F36: =SUM(C36:E36) -> 35 | G36: =F36/C$16 -> 1 | H36: Completado
B37: Modificar dockerfile con imagen adecuada (22 o 24) | C37: =COUNTIF(' Capa Integración'!X5:X16,"Completado") -> 12 | D37: =COUNTIF('Capa API'!X5:X20,"Completado") -> 16 | E37: =COUNTIF('Capa Orquestación'!X5:X11,"Completado") -> 7 | F37: =SUM(C37:E37) -> 35 | G37: =F37/C$16 -> 1 | H37: Completado
B38: Corregir statusCode y mensaje de respuesta endpoints | C38: =COUNTIF(' Capa Integración'!Y5:Y16,"Completado") -> 12 | D38: =COUNTIF('Capa API'!Y5:Y20,"Completado") -> 16 | E38: =COUNTIF('Capa Orquestación'!Y5:Y11,"Completado") -> 7 | F38: =SUM(C38:E38) -> 35 | G38: =F38/C$16 -> 1 | H38: Completado
B39: Implementar estándar de logging | C39: =COUNTIF(' Capa Integración'!Z5:Z16,"Completado") -> 12 | D39: =COUNTIF('Capa API'!Z5:Z20,"Completado") -> 16 | E39: =COUNTIF('Capa Orquestación'!Z5:Z11,"Completado") -> 7 | F39: =SUM(C39:E39) -> 35 | G39: =F39/C$16 -> 1 | H39: Completado
B40: =' Capa Integración'!AA4 -> Capt. Deployment | C40: =COUNTIF(' Capa Integración'!AA5:AA16,"Completado") -> 12 | D40: =COUNTIF('Capa API'!AA5:AA20,"Completado") -> 16 | E40: =COUNTIF('Capa Orquestación'!AA5:AA11,"Completado") -> 7 | F40: =SUM(C40:E40) -> 35 | G40: =F40/C$16 -> 1 | H40: Completado
B41: =' Capa Integración'!AB4 -> Doc API .md | C41: =COUNTIF(' Capa Integración'!AB5:AB16,"Completado") -> 12 | D41: =COUNTIF('Capa API'!AB5:AB20,"Completado") -> 15 | E41: =COUNTIF('Capa Orquestación'!AB5:AB11,"Completado") -> 7 | F41: =SUM(C41:E41) -> 34 | G41: =F41/C$16 -> 0.97142857 | H41: Completado
B42: =' Capa Integración'!AC4 -> Carga imagen al ACR | C42: =COUNTIF(' Capa Integración'!AC5:AC16,"Completado") -> 12 | D42: =COUNTIF('Capa API'!AC5:AC20,"Completado") -> 14 | E42: =COUNTIF('Capa Orquestación'!AC5:AC11,"Completado") -> 7 | F42: =SUM(C42:E42) -> 33 | G42: =F42/C$16 -> 0.94285714 | H42: Completado
B43: =' Capa Integración'!AD4 -> Deploy DEV | C43: =COUNTIF(' Capa Integración'!AD5:AD16,"Completado") -> 12 | D43: =COUNTIF('Capa API'!AD5:AD20,"Completado") -> 13 | E43: =COUNTIF('Capa Orquestación'!AD5:AD11,"Completado") -> 5 | F43: =SUM(C43:E43) -> 30 | G43: =F43/C$16 -> 0.85714286 | H43: En Curso
B44: =' Capa Integración'!AE4 -> Valid. Servicio DEV | C44: =COUNTIF(' Capa Integración'!AE5:AE16,"Completado") -> 12 | D44: =COUNTIF('Capa API'!AE5:AE20,"Completado") -> 4 | E44: =COUNTIF('Capa Orquestación'!AE5:AE11,"Completado") -> 0 | F44: =SUM(C44:E44) -> 16 | G44: =F44/C$16 -> 0.45714286 | H44: En Curso
B45: =' Capa Integración'!AF4 -> Deploy UAT - Pre PRD | C45: =COUNTIF(' Capa Integración'!AF5:AF16,"Completado") -> 0 | D45: =COUNTIF('Capa API'!AF5:AF20,"Completado") -> 0 | E45: =COUNTIF('Capa Orquestación'!AF5:AF11,"Completado") -> 0 | F45: =SUM(C45:E45) -> 0 | G45: =F45/C$16 -> 0 | H45: Pendiente
B48: Actividad | C48: % Completado
B49: Comp. Gluon | C49: =G21 -> 1
...

Sheet  Capa Integración
B2: MIGRACIÓN BACKEND — CAPA INTEGRACIÓN
H3: ACTIVIDADES DE DESARROLLO (21 tareas) | AC3: DESPLIEGUE Y VALIDACIÓN
A4: # | B4: Proyecto | C4: Componente / API | D4: Resp. Dev / DevOps | E4: LP | F4: Ver. | G4: % Avance | H4: Comp. Gluon | I4: Java 11→21 | J4: SQL→ Postgres | K4: Arq. Gluon | L4: Deploy YMLs | M4: Swagger .yml | N4: Build & Dev | O4: Validar Endp. | P4: Unit Tests | Q4: GitHub /Azure | R4: PRs Dep/Dev | S4: Sonar Qube | T4: Node24 Laptop | U4: Dist. Tracing | V4: Prop. Headers | W4: Valid. Headers | X4: Dockerf. Imagen | Y4: StatusCode Resp | Z4: Std. Logging | AA4: Capt. Deployment | AB4: Doc API .md | AC4: Carga imagen al ACR | AD4: Deploy DEV | AE4: Valid. Servicio DEV | AF4: Deploy UAT - Pre PRD | AH4: OBS | AI4: APIM
A5: 1 | B5: Core_Surgir | C5: sur-auth-broker-insurance | D5: Jairo | E5: NodeJS | F5: 24 | G5: =IFERROR(COUNTIF(H5:AF5,"Completado")/(COUNTA(H5:AF5)-COUNTIF(H5:AF5,"N/A")),0) -> 0.96 | H5: Completado | I5: Completado | J5: Completado | K5: Completado | L5: Completado | M5: Completado | N5: Completado | O5: Completado | P5: Completado | Q5: Completado | R5: Completado | S5: Completado | T5: Completado | U5: Completado | V5: Completado | W5: Completado | X5: Completado | Y5: Completado | Z5: Completado | AA5: Completado | AB5: Completado | AC5: Completado | AD5: Completado | AE5: Completado | AF5: Pendiente | AG5: ONB / APP Surgir | AI5: https://perd3zu1amscapgobcomm001.azure-api.net/API/BROKER-INSURANCE/DEV/V1
A6: 2 | B6: Core_Surgir | C6: sur-auth-mid-buro | D6: Gonzalo | E6: NodeJS | F6: 24 | G6: =IFERROR(COUNTIF(H6:AF6,"Completado")/(COUNTA(H6:AF6)-COUNTIF(H6:AF6,"N/A")),0) -> 0.96 | H6: Completado | I6: Completado | J6: Completado | K6: Completado | L6: Completado | M6: Completado | N6: Completado | O6: Completado | P6: Completado | Q6: Completado | R6: Completado | S6: Completado | T6: Completado | U6: Completado | V6: Completado | W6: Completado | X6: Completado | Y6: Completado | Z6: Completado | AA6: Completado | AB6: Completado | AC6: Completado | AD6: Completado | AE6: Completado | AF6: Pendiente | AG6: APP Surgir | AH6: Salida a internet para consumir API terceros | AI6: https://perd3zu1amscapgobcomm001.azure-api.net/API/MID-BURO/DEV/V1
A7: 3 | B7: Core_Surgir | C7: sur-auth-mid-core-bank | D7: Gonzalo | E7: NodeJS | F7: 24 | G7: =IFERROR(COUNTIF(H7:AF7,"Completado")/(COUNTA(H7:AF7)-COUNTIF(H7:AF7,"N/A")),0) -> 0.96 | H7: Completado | I7: Completado | J7: Completado | K7: Completado | L7: Completado | M7: Completado | N7: Completado | O7: Completado | P7: Completado | Q7: Completado | R7: Completado | S7: Completado | T7: Completado | U7: Completado | V7: Completado | W7: Completado | X7: Completado | Y7: Completado | Z7: Completado | AA7: Completado | AB7: Completado | AC7: Completado | AD7: Completado | AE7: Completado | AF7: Pendiente | AG7: Todos | AH7: CERRADO - Bloqueante Redis | AI7: https://perd3zu1amscapgobcomm001.azure-api.net/API/MID-CORE-BANK/DEV/V1
A8: 4 | B8: Core_Surgir | C8: sur-auth-messenger | D8: Gonzalo | E8: NodeJS | F8: 24 | G8: =IFERROR(COUNTIF(H8:AF8,"Completado")/(COUNTA(H8:AF8)-COUNTIF(H8:AF8,"N/A")),0) -> 0.96 | H8: Completado | I8: Completado | J8: Completado | K8: Completado | L8: Completado | M8: Completado | N8: Completado | O8: Completado | P8: Completado | Q8: Completado | R8: Completado | S8: Completado | T8: Completado | U8: Completado | V8: Completado | W8: Completado | X8: Completado | Y8: Completado | Z8: Completado | AA8: Completado | AB8: Completado | AC8: Completado | AD8: Completado | AE8: Completado | AF8: Pendiente | AG8: Web | AH8: Salida a internet para consumir API terceros | AI8: https://perd3zu1amscapgobcomm001.azure-api.net/API/MESSENGER/DEV/V1
A9: 5 | B9: Core_Surgir | C9: sur-auth-ms-plaft | D9: Galvez | E9: Java | F9: 21 | G9: =IFERROR(COUNTIF(H9:AF9,"Completado")/(COUNTA(H9:AF9)-COUNTIF(H9:AF9,"N/A")),0) -> 0.96 | H9: Completado | I9: Completado | J9: Completado | K9: Completado | L9: Completado | M9: Completado | N9: Completado | O9: Completado | P9: Completado | Q9: Completado | R9: Completado | S9: Completado | T9: Completado | U9: Completado | V9: Completado | W9: Completado | X9: Completado | Y9: Completado | Z9: Completado | AA9: Completado | AB9: Completado | AC9: Completado | AD9: Completado | AE9: Completado | AF9: Pendiente | AG9: APP Surgir | AI9: https://perd3zu1amscapgobcomm001.azure-api.net/API/MS-PLAFT/DEV/V1
A10: 6 | B10: Core_Surgir | C10: sur-auth-auth-business | D10: Ybeth / Jairo | E10: NodeJS | F10: 24 | G10: =IFERROR(COUNTIF(H10:AF10,"Completado")/(COUNTA(H10:AF10)-COUNTIF(H10:AF10,"N/A")),0) -> 0.96 | H10: Completado | I10: Completado | J10: Completado | K10: Completado | L10: Completado | M10: Completado | N10: Completado | O10: Completado | P10: Completado | Q10: Completado | R10: Completado | S10: Completado | T10: Completado | U10: Completado | V10: Completado | W10: Completado | X10: Completado | Y10: Completado | Z10: Completado | AA10: Completado | AB10: Completado | AC10: Completado | AD10: Completado | AE10: Completado | AF10: Pendiente | AG10: Todos | AI10: https://perd3zu1amscapgobcomm001.azure-api.net/API/AUTH-BUSINESS/DEV/V1
A11: 7 | B11: Core_Surgir | C11: sur-auth-base | D11: Ybeth / Gonzalo | E11: NodeJS | F11: 24 | G11: =IFERROR(COUNTIF(H11:AF11,"Completado")/(COUNTA(H11:AF11)-COUNTIF(H11:AF11,"N/A")),0) -> 0.96 | H11: Completado | I11: Completado | J11: Completado | K11: Completado | L11: Completado | M11: Completado | N11: Completado | O11: Completado | P11: Completado | Q11: Completado | R11: Completado | S11: Completado | T11: Completado | U11: Completado | V11: Completado | W11: Completado | X11: Completado | Y11: Completado | Z11: Completado | AA11: Completado | AB11: Completado | AC11: Completado | AD11: Completado | AE11: Completado | AF11: Pendiente | AG11: ONB / APP Surgir | AI11: https://perd3zu1amscapgobcomm001.azure-api.net/API/BASES/DEV/V1
A12: 9 | B12: Onboarding | C12: sur-auth-msapimidbusiness | D12: Gonzalo | E12: NodeJS | F12: 24 | G12: =IFERROR(COUNTIF(H12:AF12,"Completado")/(COUNTA(H12:AF12)-COUNTIF(H12:AF12,"N/A")),0) -> 0.96 | H12: Completado | I12: Completado | J12: Completado | K12: Completado | L12: Completado | M12: Completado | N12: Completado | O12: Completado | P12: Completado | Q12: Completado | R12: Completado | S12: Completado | T12: Completado | U12: Completado | V12: Completado | W12: Completado | X12: Completado | Y12: Completado | Z12: Completado | AA12: Completado | AB12: Completado | AC12: Completado | AD12: Completado | AE12: Completado | AF12: Pendiente | AG12: ONB | AI12: https://perd3zu1amscapgobcomm001.azure-api.net/API/MSAPIMIDBUSINESS/DEV/V1
A13: 8 | B13: Onboarding | C13: sur-auth-msapimidloan | D13: Ybeth / Gonzalo | E13: NodeJS | F13: 24 | G13: =IFERROR(COUNTIF(H13:AF13,"Completado")/(COUNTA(H13:AF13)-COUNTIF(H13:AF13,"N/A")),0) -> 0.96 | H13: Completado | I13: Completado | J13: Completado | K13: Completado | L13: Completado | M13: Completado | N13: Completado | O13: Completado | P13: Completado | Q13: Completado | R13: Completado | S13: Completado | T13: Completado | U13: Completado | V13: Completado | W13: Completado | X13: Completado | Y13: Completado | Z13: Completado | AA13: Completado | AB13: Completado | AC13: Completado | AD13: Completado | AE13: Completado | AF13: Pendiente | AG13: ONB | AH13: Tiene la clase pero no usa Redis. | AI13: https://perd3zu1amscapgobcomm001.azure-api.net/API/MSAPIMIDLOAN/DEV/V1
A14: 10 | B14: Onboarding | C14: sur-auth-msapimidcustomer | D14: Jairo | E14: NodeJS | F14: 24 | G14: =IFERROR(COUNTIF(H14:AF14,"Completado")/(COUNTA(H14:AF14)-COUNTIF(H14:AF14,"N/A")),0) -> 0.96 | H14: Completado | I14: Completado | J14: Completado | K14: Completado | L14: Completado | M14: Completado | N14: Completado | O14: Completado | P14: Completado | Q14: Completado | R14: Completado | S14: Completado | T14: Completado | U14: Completado | V14: Completado | W14: Completado | X14: Completado | Y14: Completado | Z14: Completado | AA14: Completado | AB14: Completado | AC14: Completado | AD14: Completado | AE14: Completado | AF14: Pendiente | AG14: ONB | AI14: https://perd3zu1amscapgobcomm001.azure-api.net/API/MSAPIMIDCUSTOMER/DEV/V1
A15: 11 | B15: Onboarding | C15: sur-auth-msmidzytrust | D15: Alvaro | E15: NodeJS | F15: 24 | G15: =IFERROR(COUNTIF(H15:AF15,"Completado")/(COUNTA(H15:AF15)-COUNTIF(H15:AF15,"N/A")),0) -> 0.96 | H15: Completado | I15: Completado | J15: Completado | K15: Completado | L15: Completado | M15: Completado | N15: Completado | O15: Completado | P15: Completado | Q15: Completado | R15: Completado | S15: Completado | T15: Completado | U15: Completado | V15: Completado | W15: Completado | X15: Completado | Y15: Completado | Z15: Completado | AA15: Completado | AB15: Completado | AC15: Completado | AD15: Completado | AE15: Completado | AF15: Pendiente | AG15: ONB | AH15: Bloqueado conexión a Postgresql (Zytrust). | AI15: https://perd3zu1amscapgobcomm001.azure-api.net/API/MSMIDZYTRUST/DEV/V1
A16: 12 | B16: Onboarding | C16: sur-auth-ms-mid-identy | D16: Brayan | E16: NodeJS | F16: 24 | G16: =IFERROR(COUNTIF(H16:AF16,"Completado")/(COUNTA(H16:AF16)-COUNTIF(H16:AF16,"N/A")),0) -> 0.96 | H16: Completado | I16: Completado | J16: Completado | K16: Completado | L16: Completado | M16: Completado | N16: Completado | O16: Completado | P16: Completado | Q16: Completado | R16: Completado | S16: Completado | T16: Completado | U16: Completado | V16: Completado | W16: Completado | X16: Completado | Y16: Completado | Z16: Completado | AA16: Completado | AB16: Completado | AC16: Completado | AD16: Completado | AE16: Completado | AF16: Pendiente | AG16: ONB | AH16: Salida a internet para consumir API terceros | AI16: https://perd3zu1amscapgobcomm001.azure-api.net/API/MS-MID-IDENTY/DEV/V1
A17: TOTAL APIs: 12 | Avance global de actividades: | G17: =IFERROR(AVERAGE(G5:G16),0) -> 0.96
A18: Completado por actividad: | H18: =COUNTIF(H5:H16,"Completado") -> 12 | I18: =COUNTIF(I5:I16,"Completado") -> 12 | J18: =COUNTIF(J5:J16,"Completado") -> 12 | K18: =COUNTIF(K5:K16,"Completado") -> 12 | L18: =COUNTIF(L5:L16,"Completado") -> 12 | M18: =COUNTIF(M5:M16,"Completado") -> 12 | N18: =COUNTIF(N5:N16,"Completado") -> 12 | O18: =COUNTIF(O5:O16,"Completado") -> 12 | ... AF18: =COUNTIF(AF5:AF16,"Completado") -> 0
A20: LEYENDA: | E20: Completado | F20: En Curso | G20: Pendiente | H20: N/A | AD20: * se espera terminar el martes 31/03

Sheet Capa API
B2: MIGRACIÓN BACKEND — CAPA API
H3: ACTIVIDADES DE DESARROLLO (21 tareas) | AC3: DESPLIEGUE Y VALIDACIÓN
A4: # | B4: Proyecto | C4: Componente / API | D4: Resp. Dev / DevOps | E4: LP | F4: Ver. | G4: % Avance | H4: Comp. Gluon | I4: Java 11→21 | J4: SQL→ Postgres | K4: Arq. Gluon | L4: Deploy YMLs | M4: Swagger .yml | N4: Build & Dev | O4: Validar Endp. | P4: Unit Tests | Q4: GitHub /Azure | R4: PRs Dep/Dev | S4: Sonar Qube | T4: Node24 Laptop | U4: Dist. Tracing | V4: Prop. Headers | W4: Valid. Headers | X4: Dockerf. Imagen | Y4: StatusCode Resp | Z4: Std. Logging | AA4: =' Capa Integración'!AA4 -> Capt. Deployment | AB4: =' Capa Integración'!AB4 -> Doc API .md | AC4: =' Capa Integración'!AC4 -> Carga imagen al ACR | AD4: =' Capa Integración'!AD4 -> Deploy DEV | AE4: =' Capa Integración'!AE4 -> Valid. Servicio DEV | AF4: =' Capa Integración'!AF4 -> Deploy UAT - Pre PRD
A5: 1 | B5: Core_Surgir | C5: sur-auth-authorizers | D5: Galvez / Gonzalo | E5: Java | F5: 21 | G5: =IFERROR(COUNTIF(H5:AF5,"Completado")/(COUNTA(H5:AF5)-COUNTIF(H5:AF5,"N/A")),0) -> 0.92 | H5: Completado | I5: Completado | J5: Completado | K5: Completado | L5: Completado | M5: Completado | N5: Completado | O5: Completado | P5: Completado | Q5: Completado | R5: Completado | S5: Completado | T5: Completado | U5: Completado | V5: Completado | W5: Completado | X5: Completado | Y5: Completado | Z5: Completado | AA5: Completado | AB5: Completado | AC5: Completado | AD5: Completado | AE5: En Curso | AF5: Pendiente | AG5: Sistematica / APP Surgir | AH5: Bloqueado conexión a Postgresql (Minerva). | AI5: https://perd3zu1amscapgobcomm001.azure-api.net/API/AUTHORIZERS/DEV/V1
A6: 2 | B6: Core_Surgir | C6: sur-auth-disbursement | D6: Khalid | E6: NodeJS | F6: 24 | G6: =IFERROR(COUNTIF(H6:AF6,"Completado")/(COUNTA(H6:AF6)-COUNTIF(H6:AF6,"N/A")),0) -> 0.92 | H6: Completado | I6: Completado | J6: Completado | K6: Completado | L6: Completado | M6: Completado | N6: Completado | O6: Completado | P6: Completado | Q6: Completado | R6: Completado | S6: Completado | T6: Completado | U6: Completado | V6: Completado | W6: Completado | X6: Completado | Y6: Completado | Z6: Completado | AA6: Completado | AB6: Completado | AC6: Completado | AD6: Completado | AE6: En Curso | AF6: Pendiente | AG6: Sistematica / APP Surgir | AH6: Pendiente la creación del Queue | AI6: https://perd3zu1amscapgobcomm001.azure-api.net/API/DISBURSEMENT/DEV/V1
A7: 3 | B7: Core_Surgir | C7: sur-auth-document-generator | D7: Jairo | E7: NodeJS | F7: 24 | G7: =IFERROR(COUNTIF(H7:AF7,"Completado")/(COUNTA(H7:AF7)-COUNTIF(H7:AF7,"N/A")),0) -> 0.88 | H7: Completado | I7: Completado | J7: Completado | K7: Completado | L7: Completado | M7: Completado | N7: Completado | O7: Completado | P7: Completado | Q7: Completado | R7: Completado | S7: Completado | T7: Completado | U7: Completado | V7: Completado | W7: Completado | X7: Completado | Y7: Completado | Z7: Completado | AA7: Completado | AB7: Completado | AC7: Completado | AD7: En Curso | AE7: En Curso | AF7: Pendiente | AG7: Todos | AH7: Bloqueado conexión a Postgresql (Minerva).Faltan probar 2 endpoint que consument PG | AI7: https://perd3zu1amscapgobcomm001.azure-api.net/API/DOCUMENT-GENERATOR/DEV/V1
A8: 4 | B8: Core_Surgir | C8: sur-auth-sistematica | D8: Ybeth / Khalid | E8: NodeJS | F8: 24 | G8: =IFERROR(COUNTIF(H8:AF8,"Completado")/(COUNTA(H8:AF8)-COUNTIF(H8:AF8,"N/A")),0) -> 0.92 | H8: Completado | I8: Completado | J8: Completado | K8: Completado | L8: Completado | M8: Completado | N8: Completado | O8: Completado | P8: Completado | Q8: Completado | R8: Completado | S8: Completado | T8: Completado | U8: Completado | V8: Completado | W8: Completado | X8: Completado | Y8: Completado | Z8: Completado | AA8: Completado | AB8: Completado | AC8: Completado | AD8: Completado | AE8: En Curso | AF8: Pendiente | AG8: Sistematica | AH8: Bloqueado conexión a Postgresql (Sistematica). | AI8: https://perd3zu1amscapgobcomm002.azure-api.net/API/SISTEMATICA/DEV/V1
A9: 5 | B9: Core_Surgir | C9: sur-auth-grupal | D9: Galvez / Gonzalo | E9: Java | F9: 21 | G9: =IFERROR(COUNTIF(H9:AF9,"Completado")/(COUNTA(H9:AF9)-COUNTIF(H9:AF9,"N/A")),0) -> 0.92 | H9: Completado | I9: Completado | J9: Completado | K9: Completado | L9: Completado | M9: Completado | N9: Completado | O9: Completado | P9: Completado | Q9: Completado | R9: Completado | S9: Completado | T9: Completado | U9: Completado | V9: Completado | W9: Completado | X9: Completado | Y9: Completado | Z9: Completado | AA9: Completado | AB9: Completado | AC9: Completado | AD9: Completado | AE9: En Curso | AF9: Pendiente | AG9: APP Surgir | AH9: Bloqueado conexión a Postgresql (Minerva).
A10: 6 | B10: Core_Surgir | C10: sur-auth-digital-folder | D10: Ybeth / Khalid | E10: NodeJS | F10: 24 | G10: =IFERROR(COUNTIF(H10:AF10,"Completado")/(COUNTA(H10:AF10)-COUNTIF(H10:AF10,"N/A")),0) -> 0.92 | H10: Completado | I10: Completado | J10: Completado | K10: Completado | L10: Completado | M10: Completado | N10: Completado | O10: Completado | P10: Completado | Q10: Completado | R10: Completado | S10: Completado | T10: Completado | U10: Completado | V10: Completado | W10: Completado | X10: Completado | Y10: Completado | Z10: Completado | AA10: Completado | AB10: Completado | AC10: Completado | AD10: Completado | AE10: En Curso | AF10: Pendiente | AG10: Todos | AI10: https://perd3zu1amscapgobcomm001.azure-api.net/API/DIGITAL-FOLDER/DEV/V1
A11: 7 | B11: Core_Surgir | C11: sur-auth-compliance-risk | D11: Galvez / Gonzalo | E11: Java | F11: 21 | G11: =IFERROR(COUNTIF(H11:AF11,"Completado")/(COUNTA(H11:AF11)-COUNTIF(H11:AF11,"N/A")),0) -> 0.92 | H11: Completado | I11: Completado | J11: Completado | K11: Completado | L11: Completado | M11: Completado | N11: Completado | O11: Completado | P11: Completado | Q11: Completado | R11: Completado | S11: Completado | T11: Completado | U11: Completado | V11: Completado | W11: Completado | X11: Completado | Y11: Completado | Z11: Completado | AA11: Completado | AB11: Completado | AC11: Completado | AD11: Completado | AE11: En Curso | AF11: Pendiente | AG11: ONB / APP Surgir | AH11: Bloqueado conexión a Postgresql (Rules).
A12: 8 | B12: Core_Surgir | C12: sur-auth-send-app | D12: Gonzalo | E12: NodeJS | F12: 24 | G12: =IFERROR(COUNTIF(H12:AF12,"Completado")/(COUNTA(H12:AF12)-COUNTIF(H12:AF12,"N/A")),0) -> 0.92 | H12: Completado | I12: Completado | J12: Completado | K12: Completado | L12: Completado | M12: Completado | N12: Completado | O12: Completado | P12: Completado | Q12: Completado | R12: Completado | S12: Completado | T12: Completado | U12: Completado | V12: Completado | W12: Completado | X12: Completado | Y12: Completado | Z12: Completado | AA12: Completado | AB12: Completado | AC12: Completado | AD12: Completado | AE12: En Curso | AF12: Pendiente | AG12: ONB / APP Surgir | AI12: https://perd3zu1amscapgobcomm001.azure-api.net/API/SEND-APP/DEV/V1
A13: 9 | B13: Core_Surgir | C13: sur-auth-workflow | D13: Galvez / Gonzalo | E13: Java | F13: 21 | G13: =IFERROR(COUNTIF(H13:AF13,"Completado")/(COUNTA(H13:AF13)-COUNTIF(H13:AF13,"N/A")),0) -> 0.92 | H13: Completado | I13: Completado | J13: Completado | K13: Completado | L13: Completado | M13: Completado | N13: Completado | O13: Completado | P13: Completado | Q13: Completado | R13: Completado | S13: Completado | T13: Completado | U13: Completado | V13: Completado | W13: Completado | X13: Completado | Y13: Completado | Z13: Completado | AA13: Completado | AB13: Completado | AC13: Completado | AD13: Completado | AE13: En Curso | AF13: Pendiente | AG13: ONB / APP Surgir | AH13: Bloqueado conexión a Postgresql (Minerva). | AI13: https://perd3zu1amscapgobcomm001.azure-api.net/API/WORKFLOW/DEV/V1
A14: 10 | B14: Core_Surgir | C14: sur-auth-sase-cuma-curema | D14: Alvaro | E14: NodeJS | F14: 24 | G14: =IFERROR(COUNTIF(H14:AF14,"Completado")/(COUNTA(H14:AF14)-COUNTIF(H14:AF14,"N/A")),0) -> 0.96 | H14: Completado | I14: Completado | J14: Completado | K14: Completado | L14: Completado | M14: Completado | N14: Completado | O14: Completado | P14: Completado | Q14: Completado | R14: Completado | S14: Completado | T14: Completado | U14: Completado | V14: Completado | W14: Completado | X14: Completado | Y14: Completado | Z14: Completado | AA14: Completado | AB14: Completado | AC14: Completado | AD14: Completado | AE14: Completado | AF14: Pendiente | AG14: APP Surgir | AH14: Bloqueado conexión a Postgresql (Minerva). | AI14: https://perd3zu1amscapgobcomm001.azure-api.net/API/CUREMA/DEV/V1
A15: 11 | B15: Core_Surgir | C15: sur-auth-opex-trba-crma | D15: Alvaro | E15: NodeJS | F15: 24 | G15: =IFERROR(COUNTIF(H15:AF15,"Completado")/(COUNTA(H15:AF15)-COUNTIF(H15:AF15,"N/A")),0) -> 0.96 | H15: Completado | I15: Completado | J15: Completado | K15: Completado | L15: Completado | M15: Completado | N15: Completado | O15: Completado | P15: Completado | Q15: Completado | R15: Completado | S15: Completado | T15: Completado | U15: Completado | V15: Completado | W15: Completado | X15: Completado | Y15: Completado | Z15: Completado | AA15: Completado | AB15: Completado | AC15: Completado | AD15: Completado | AE15: Completado | AF15: Pendiente | AG15: APP Surgir | AI15: https://perd3zu1amscapgobcomm001.azure-api.net/API/OPEX-TRBA-CRMA/DEV/V1
A16: 12 | B16: Onboarding | C16: sur-auth-msapicustomer | D16: Rosa | E16: NodeJS | F16: 24 | G16: =IFERROR(COUNTIF(H16:AF16,"Completado")/(COUNTA(H16:AF16)-COUNTIF(H16:AF16,"N/A")),0) -> 0.84 | H16: Completado | I16: Completado | J16: Completado | K16: Completado | L16: Completado | M16: Completado | N16: Completado | O16: Completado | P16: Completado | Q16: Completado | R16: Completado | S16: Completado | T16: Completado | U16: Completado | V16: Completado | W16: Completado | X16: Completado | Y16: Completado | Z16: Completado | AA16: Completado | AB16: Completado | AC16: No aplica | AD16: No aplica | AE16: No aplica | AF16: No aplica | AG16: - | AH16: Servicio no se encuentra en PRD en Surgir Cloud | AI16: https://perd3zu1amscapgobcomm001.azure-api.net/API/MSAPICUSTOMER/DEV/V1
A17: 13 | B17: Onboarding | C17: sur-auth-pasarela-pagos | D17: Alvaro | E17: NodeJS | F17: 24 | G17: =IFERROR(COUNTIF(H17:AF17,"Completado")/(COUNTA(H17:AF17)-COUNTIF(H17:AF17,"N/A")),0) -> 0.8 | H17: Completado | I17: Completado | J17: Completado | K17: Completado | L17: Completado | M17: Completado | N17: Completado | O17: Completado | P17: Completado | Q17: Completado | R17: Completado | S17: Completado | T17: Completado | U17: Completado | V17: Completado | W17: Completado | X17: Completado | Y17: Completado | Z17: Completado | AA17: Completado | AB17: No aplica | AC17: No aplica | AD17: No aplica | AE17: No aplica | AF17: No aplica | AG17: - | AH17: Servicio no se encuentra en PRD en Surgir Cloud
A18: 14 | B18: Onboarding | C18: sur-auth-msapiloan | D18: Khalid | E18: NodeJS | F18: 24 | G18: =IFERROR(COUNTIF(H18:AF18,"Completado")/(COUNTA(H18:AF18)-COUNTIF(H18:AF18,"N/A")),0) -> 0.96 | H18: Completado | I18: Completado | J18: Completado | K18: Completado | L18: Completado | M18: Completado | N18: Completado | O18: Completado | P18: Completado | Q18: Completado | R18: Completado | S18: Completado | T18: Completado | U18: Completado | V18: Completado | W18: Completado | X18: Completado | Y18: Completado | Z18: Completado | AA18: Completado | AB18: Completado | AC18: Completado | AD18: Completado | AE18: Completado | AF18: Pendiente | AG18: ONB / APP Surgir | AH18: Bloqueado conexión a Postgresql (Minerva). | AI18: https://perd3zu1amscapgobcomm001.azure-api.net/API/MSAPILOAN/DEV/V1
A19: 15 | B19: Onboarding | C19: sur-auth-msapibusiness | D19: Alvaro | E19: NodeJS | F19: 24 | G19: =IFERROR(COUNTIF(H19:AF19,"Completado")/(COUNTA(H19:AF19)-COUNTIF(H19:AF19,"N/A")),0) -> 0.92 | H19: Completado | I19: Completado | J19: Completado | K19: Completado | L19: Completado | M19: Completado | N19: Completado | O19: Completado | P19: Completado | Q19: Completado | R19: Completado | S19: Completado | T19: Completado | U19: Completado | V19: Completado | W19: Completado | X19: Completado | Y19: Completado | Z19: Completado | AA19: Completado | AB19: Completado | AC19: Completado | AD19: Completado | AE19: En Curso | AF19: Pendiente | AG19: ONB / APP Surgir | AH19: Bloqueado conexión a Postgresql (Minerva). | AI19: https://perd3zu1amscapgobcomm001.azure-api.net/API/MSAPIBUSINESS/DEV/V1
A20: 16 | B20: Web Surgir | C20: sur-auth-web-backend | D20: Khalid | E20: NodeJS | F20: 24 | G20: =IFERROR(COUNTIF(H20:AF20,"Completado")/(COUNTA(H20:AF20)-COUNTIF(H20:AF20,"N/A")),0) -> 0.96 | H20: Completado | I20: Completado | J20: Completado | K20: Completado | L20: Completado | M20: Completado | N20: Completado | O20: Completado | P20: Completado | Q20: Completado | R20: Completado | S20: Completado | T20: Completado | U20: Completado | V20: Completado | W20: Completado | X20: Completado | Y20: Completado | Z20: Completado | AA20: Completado | AB20: Completado | AC20: Completado | AD20: Completado | AE20: Completado | AF20: Pendiente | AG20: Web | AI20: https://perd3zu1amscapgobcomm001.azure-api.net/API/WEB-BACKEND/DEV/V1
A21: TOTAL APIs: 16 | Avance global de actividades: | G21: =IFERROR(AVERAGE(G5:G20),0) -> 0.915
A22: Completado por actividad: | H22: =COUNTIF(H5:H20,"Completado") -> 16 | I22: =COUNTIF(I5:I20,"Completado") -> 16 | J22: =COUNTIF(J5:J20,"Completado") -> 16 | K22: =COUNTIF(K5:K20,"Completado") -> 16 | L22: =COUNTIF(L5:L20,"Completado") -> 16 | M22: =COUNTIF(M5:M20,"Completado") -> 16 | N22: =COUNTIF(N5:N20,"Completado") -> 16 | O22: =COUNTIF(O5:O20,"Completado") -> 16 | ... AF22: =COUNTIF(AF5:AF20,"Completado") -> 0
A24: LEYENDA: | E24: Completado | F24: En Curso | G24: Pendiente | H24: N/A

Sheet Capa Orquestación
B2: MIGRACIÓN BACKEND — CAPA ORQUESTACIÓN
H3: ACTIVIDADES DE DESARROLLO (21 tareas) | AC3: DESPLIEGUE Y VALIDACIÓN
A4: # | B4: Proyecto | C4: API / Componente | D4: Resp. | E4: LP | F4: Ver. | G4: % Avance | H4: Comp. Gluon | I4: Java 11→21 | J4: SQL→ Postgres | K4: Arq. Gluon | L4: Deploy YMLs | M4: Swagger .yml | N4: Build & Dev | O4: Validar Endp. | P4: Unit Tests | Q4: GitHub /Azure | R4: PRs Dep/Dev | S4: Sonar Qube | T4: Node24 Laptop | U4: Dist. Tracing | V4: Prop. Headers | W4: Valid. Headers | X4: Dockerf. Imagen | Y4: StatusCode Resp | Z4: Std. Logging | AA4: Capt. Deployment | AB4: Doc API .md | AC4: Carga imagen al ACR | AD4: Deploy DEV | AE4: =' Capa Integración'!AE4 -> Valid. Servicio DEV | AF4: Deploy UAT
A5: 1 | B5: Onboarding | C5: sur-auth-mstrace | D5: Brayan | E5: NodeJS | F5: 24 | G5: =IFERROR(COUNTIF(H5:AF5,"Completado")/(COUNTA(H5:AF5)-COUNTIF(H5:AF5,"N/A")),0) -> 0.88 | H5: Completado | I5: Completado | J5: Completado | K5: Completado | L5: Completado | M5: Completado | N5: Completado | O5: Completado | P5: Completado | Q5: Completado | R5: Completado | S5: Completado | T5: Completado | U5: Completado | V5: Completado | W5: Completado | X5: Completado | Y5: Completado | Z5: Completado | AA5: Completado | AB5: Completado | AC5: Completado | AD5: Pendiente | AE5: Pendiente | AF5: Pendiente | AG5: ONB | AH5: Bloqueado conexión a Postgresql (Minerva). | AI5: https://perd3zu1amscapgobcomm001.azure-api.net/API/MSTRACE/DEV/V1
A6: 2 | B6: Onboarding | C6: sur-auth-sendonb | D6: Rosa | E6: NodeJS | F6: 24 | G6: =IFERROR(COUNTIF(H6:AF6,"Completado")/(COUNTA(H6:AF6)-COUNTIF(H6:AF6,"N/A")),0) -> 0.88 | H6: Completado | I6: Completado | J6: Completado | K6: Completado | L6: Completado | M6: Completado | N6: Completado | O6: Completado | P6: Completado | Q6: Completado | R6: Completado | S6: Completado | T6: Completado | U6: Completado | V6: Completado | W6: Completado | X6: Completado | Y6: Completado | Z6: Completado | AA6: Completado | AB6: Completado | AC6: Completado | AD6: Pendiente | AE6: Pendiente | AF6: Pendiente | AG6: ONB | AH6: Consume APIs que están bloqueadas por PostgreSQL | AI6: https://perd3zu1amscapgobcomm001.azure-api.net/API/SENDONB/DEV/V1
A7: 3 | B7: Core_Surgir | C7: sur-auth-rules-evaluation | D7: Jairo | E7: NodeJS | F7: 24 | G7: =IFERROR(COUNTIF(H7:AF7,"Completado")/(COUNTA(H7:AF7)-COUNTIF(H7:AF7,"N/A")),0) -> 0.92 | H7: Completado | I7: Completado | J7: Completado | K7: Completado | L7: Completado | M7: Completado | N7: Completado | O7: Completado | P7: Completado | Q7: Completado | R7: Completado | S7: Completado | T7: Completado | U7: Completado | V7: Completado | W7: Completado | X7: Completado | Y7: Completado | Z7: Completado | AA7: Completado | AB7: Completado | AC7: Completado | AD7: Completado | AE7: Pendiente | AF7: Pendiente | AG7: APP Surgir | AI7: https://perd3zu1amscapgobcomm001.azure-api.net/API/RULES-EVALUATION/DEV/V1
A8: 4 | B8: Core_Surgir | C8: sur-auth-broker-functions | D8: Jairo | E8: NodeJS | F8: 24 | G8: =IFERROR(COUNTIF(H8:AF8,"Completado")/(COUNTA(H8:AF8)-COUNTIF(H8:AF8,"N/A")),0) -> 0.92 | H8: Completado | I8: Completado | J8: Completado | K8: Completado | L8: Completado | M8: Completado | N8: Completado | O8: Completado | P8: Completado | Q8: Completado | R8: Completado | S8: Completado | T8: Completado | U8: Completado | V8: Completado | W8: Completado | X8: Completado | Y8: Completado | Z8: Completado | AA8: Completado | AB8: Completado | AC8: Completado | AD8: Completado | AE8: En Curso | AF8: Pendiente | AG8: APP Surgir | AI8: https://perd3zu1amscapgobcomm001.azure-api.net/API/BROKER-FUNCTIONS/DEV/V1
A9: 5 | B9: Core_Surgir | C9: sur-auth-fn-system-auth-core-code | D9: Rosa / Khalid | E9: NodeJS | F9: 24 | G9: =IFERROR(COUNTIF(H9:AF9,"Completado")/(COUNTA(H9:AF9)-COUNTIF(H9:AF9,"N/A")),0) -> 0.92 | H9: Completado | I9: Completado | J9: Completado | K9: Completado | L9: Completado | M9: Completado | N9: Completado | O9: Completado | P9: Completado | Q9: Completado | R9: Completado | S9: Completado | T9: Completado | U9: Completado | V9: Completado | W9: Completado | X9: Completado | Y9: Completado | Z9: Completado | AA9: Completado | AB9: Completado | AC9: Completado | AD9: Completado | AE9: Pendiente | AF9: Pendiente | AG9: Todos | AI9: https://perd3zu1amscapgobcomm001.azure-api.net/API/FN-SYSTEM-AUTH-CORE-CODE/DEV/V1
A10: 6 | B10: Core_Surgir | C10: sur-auth-report-workflow | D10: Ybeth / Khalid | E10: NodeJS | F10: 24 | G10: =IFERROR(COUNTIF(H10:AF10,"Completado")/(COUNTA(H10:AF10)-COUNTIF(H10:AF10,"N/A")),0) -> 0.92 | H10: Completado | I10: Completado | J10: Completado | K10: Completado | L10: Completado | M10: Completado | N10: Completado | O10: Completado | P10: Completado | Q10: Completado | R10: Completado | S10: Completado | T10: Completado | U10: Completado | V10: Completado | W10: Completado | X10: Completado | Y10: Completado | Z10: Completado | AA10: Completado | AB10: Completado | AC10: Completado | AD10: Completado | AE10: En Curso | AF10: Pendiente | AG10: APP Surgir | AH10: Bloqueado conexión a Postgresql (Minerva). | AI10: https://perd3zu1amscapgobcomm001.azure-api.net/API/REPORT-WORKFLOW/DEV/V1
A11: 7 | B11: Core_Surgir | C11: sur-auth-fn-variables-provider | D11: Gonzalo | E11: NodeJS | F11: 24 | G11: =IFERROR(COUNTIF(H11:AF11,"Completado")/(COUNTA(H11:AF11)-COUNTIF(H11:AF11,"N/A")),0) -> 0.92 | H11: Completado | I11: Completado | J11: Completado | K11: Completado | L11: Completado | M11: Completado | N11: Completado | O11: Completado | P11: Completado | Q11: Completado | R11: Completado | S11: Completado | T11: Completado | U11: Completado | V11: Completado | W11: Completado | X11: Completado | Y11: Completado | Z11: Completado | AA11: Completado | AB11: Completado | AC11: Completado | AD11: Completado | AE11: En Curso | AF11: Pendiente | AG11: APP Surgir | AI11: https://perd3zu1amscapgobcomm001.azure-api.net/API/FN-VARIABLES-PROVIDER/DEV/V1
A12: TOTAL APIs: 7 | Avance global de actividades: | G12: =IFERROR(AVERAGE(G5:G11),0) -> 0.90857143
A13: Completado por actividad: | H13: =COUNTIF(H5:H11,"Completado") -> 7 | I13: =COUNTIF(I5:I11,"Completado") -> 7 | J13: =COUNTIF(J5:J11,"Completado") -> 7 | K13: =COUNTIF(K5:K11,"Completado") -> 7 | L13: =COUNTIF(L5:L11,"Completado") -> 7 | M13: =COUNTIF(M5:M11,"Completado") -> 7 | N13: =COUNTIF(N5:N11,"Completado") -> 7 | O13: =COUNTIF(O5:O11,"Completado") -> 7 | ... AF13: =COUNTIF(AF5:AF11,"Completado") -> 0
A15: LEYENDA: | E15: Completado | F15: En Curso | G15: Pendiente | H15: N/A

Sheet Plan de Deploy
B2: PLAN DE DEPLOY Y VALIDACIÓN — DEV / UAT
B4: API | C4: Capa | D4: Estado Dev Actividades | E4: =' Capa Integración'!AC4 -> Carga imagen al ACR | F4: =' Capa Integración'!AD4 -> Deploy DEV | G4: =' Capa Integración'!AE4 -> Valid. Servicio DEV | H4: =' Capa Integración'!AF4 -> Deploy UAT - Pre PRD | I4: Criterio de Aceptacion DEV
B5: =' Capa Integración'!C5 -> sur-auth-broker-insurance | C5: Integración | D5: =_xlfn.CONCAT(INT((COUNTIF(' Capa Integración'!H5:AB5,"Completado")*100)/21), "% - ", IF(INT((COUNTIF(' Capa Integración'!H5:AB5,"Completado")*100)/21)=100,"Completado",IF(INT((COUNTIF(' Capa Integración'!H5:AB5,"Completado")*100)/21)=0,"Pendiente","En Curso"))) -> 100% - Completado | E5: =' Capa Integración'!AC5 -> Completado | F5: =' Capa Integración'!AD5 -> Completado | G5: =' Capa Integración'!AE5 -> Completado | H5: =' Capa Integración'!AF5 -> Pendiente | I5: Endpoints OK + Headers + Logs + SonarQube Pass
B6: =' Capa Integración'!C6 -> sur-auth-mid-buro | C6: Integración | D6: =_xlfn.CONCAT(INT((COUNTIF(' Capa Integración'!H6:AB6,"Completado")*100)/21), "% - ", IF(INT((COUNTIF(' Capa Integración'!H6:AB6,"Completado")*100)/21)=100,"Completado",IF(INT((COUNTIF(' Capa Integración'!H6:AB6,"Completado")*100)/21)=0,"Pendiente","En Curso"))) -> 100% - Completado | E6: =' Capa Integración'!AC6 -> Completado | F6: =' Capa Integración'!AD6 -> Completado | G6: =' Capa Integración'!AE6 -> Completado | H6: =' Capa Integración'!AF6 -> Pendiente | I6: Endpoints OK + Headers + Logs + SonarQube Pass
B7: =' Capa Integración'!C7 -> sur-auth-mid-core-bank | C7: Integración | D7: =_xlfn.CONCAT(INT((COUNTIF(' Capa Integración'!H7:AB7,"Completado")*100)/21), "% - ", IF(INT((COUNTIF(' Capa Integración'!H7:AB7,"Completado")*100)/21)=100,"Completado",IF(INT((COUNTIF(' Capa Integración'!H7:AB7,"Completado")*100)/21)=0,"Pendiente","En Curso"))) -> 100% - Completado | E7: =' Capa Integración'!AC7 -> Completado | F7: =' Capa Integración'!AD7 -> Completado | G7: =' Capa Integración'!AE7 -> Completado | H7: =' Capa Integración'!AF7 -> Pendiente | I7: Endpoints OK + Headers + Logs + SonarQube Pass
B8: =' Capa Integración'!C8 -> sur-auth-messenger | C8: Integración | D8: =_xlfn.CONCAT(INT((COUNTIF(' Capa Integración'!H8:AB8,"Completado")*100)/21), "% - ", IF(INT((COUNTIF(' Capa Integración'!H8:AB8,"Completado")*100)/21)=100,"Completado",IF(INT((COUNTIF(' Capa Integración'!H8:AB8,"Completado")*100)/21)=0,"Pendiente","En Curso"))) -> 100% - Completado | E8: =' Capa Integración'!AC8 -> Completado | F8: =' Capa Integración'!AD8 -> Completado | G8: =' Capa Integración'!AE8 -> Completado | H8: =' Capa Integración'!AF8 -> Pendiente | I8: Endpoints OK + Headers + Logs + SonarQube Pass
B9: =' Capa Integración'!C9 -> sur-auth-ms-plaft | C9: Integración | D9: =_xlfn.CONCAT(INT((COUNTIF(' Capa Integración'!H9:AB9,"Completado")*100)/21), "% - ", IF(INT((COUNTIF(' Capa Integración'!H9:AB9,"Completado")*100)/21)=100,"Completado",IF(INT((COUNTIF(' Capa Integración'!H9:AB9,"Completado")*100)/21)=0,"Pendiente","En Curso"))) -> 100% - Completado | E9: =' Capa Integración'!AC9 -> Completado | F9: =' Capa Integración'!AD9 -> Completado | G9: =' Capa Integración'!AE9 -> Completado | H9: =' Capa Integración'!AF9 -> Pendiente | I9: Endpoints OK + Headers + Logs + SonarQube Pass
B10: =' Capa Integración'!C10 -> sur-auth-auth-business | C10: Integración | D10: =_xlfn.CONCAT(INT((COUNTIF(' Capa Integración'!H10:AB10,"Completado")*100)/21), "% - ", IF(INT((COUNTIF(' Capa Integración'!H10:AB10,"Completado")*100)/21)=100,"Completado",IF(INT((COUNTIF(' Capa Integración'!H10:AB10,"Completado")*100)/21)=0,"Pendiente","En Curso"))) -> 100% - Completado | E10: =' Capa Integración'!AC10 -> Completado | F10: =' Capa Integración'!AD10 -> Completado | G10: =' Capa Integración'!AE10 -> Completado | H10: =' Capa Integración'!AF10 -> Pendiente | I10: Endpoints OK + Headers + Logs + SonarQube Pass
B11: =' Capa Integración'!C11 -> sur-auth-base | C11: Integración | D11: =_xlfn.CONCAT(INT((COUNTIF(' Capa Integración'!H11:AB11,"Completado")*100)/21), "% - ", IF(INT((COUNTIF(' Capa Integración'!H11:AB11,"Completado")*100)/21)=100,"Completado",IF(INT((COUNTIF(' Capa Integración'!H11:AB11,"Completado")*100)/21)=0,"Pendiente","En Curso"))) -> 100% - Completado | E11: =' Capa Integración'!AC11 -> Completado | F11: =' Capa Integración'!AD11 -> Completado | G11: =' Capa Integración'!AE11 -> Completado | H11: =' Capa Integración'!AF11 -> Pendiente | I11: Endpoints OK + Headers + Logs + SonarQube Pass
B12: =' Capa Integración'!C13 -> sur-auth-msapimidloan | C12: Integración | D12: =_xlfn.CONCAT(INT((COUNTIF(' Capa Integración'!H13:AB13,"Completado")*100)/21), "% - ", IF(INT((COUNTIF(' Capa Integración'!H13:AB13,"Completado")*100)/21)=100,"Completado",IF(INT((COUNTIF(' Capa Integración'!H13:AB13,"Completado")*100)/21)=0,"Pendiente","En Curso"))) -> 100% - Completado | E12: =' Capa Integración'!AC13 -> Completado | F12: =' Capa Integración'!AD13 -> Completado | G12: =' Capa Integración'!AE13 -> Completado | H12: =' Capa Integración'!AF13 -> Pendiente | I12: Endpoints OK + Headers + Logs + SonarQube Pass
B13: =' Capa Integración'!C12 -> sur-auth-msapimidbusiness | C13: Integración | D13: =_xlfn.CONCAT(INT((COUNTIF(' Capa Integración'!H12:AB12,"Completado")*100)/21), "% - ", IF(INT((COUNTIF(' Capa Integración'!H12:AB12,"Completado")*100)/21)=100,"Completado",IF(INT((COUNTIF(' Capa Integración'!H12:AB12,"Completado")*100)/21)=0,"Pendiente","En Curso"))) -> 100% - Completado | E13: =' Capa Integración'!AC12 -> Completado | F13: =' Capa Integración'!AD12 -> Completado | G13: =' Capa Integración'!AE14 -> Completado | H13: =' Capa Integración'!AF12 -> Pendiente | I13: Endpoints OK + Headers + Logs + SonarQube Pass
B14: =' Capa Integración'!C14 -> sur-auth-msapimidcustomer | C14: Integración | D14: =_xlfn.CONCAT(INT((COUNTIF(' Capa Integración'!H14:AB14,"Completado")*100)/21), "% - ", IF(INT((COUNTIF(' Capa Integración'!H14:AB14,"Completado")*100)/21)=100,"Completado",IF(INT((COUNTIF(' Capa Integración'!H14:AB14,"Completado")*100)/21)=0,"Pendiente","En Curso"))) -> 100% - Completado | E14: =' Capa Integración'!AC14 -> Completado | F14: =' Capa Integración'!AD14 -> Completado | G14: =' Capa Integración'!AE14 -> Completado | H14: =' Capa Integración'!AF14 -> Pendiente | I14: Endpoints OK + Headers + Logs + SonarQube Pass
B15: =' Capa Integración'!C15 -> sur-auth-msmidzytrust | C15: Integración | D15: =_xlfn.CONCAT(INT((COUNTIF(' Capa Integración'!H15:AB15,"Completado")*100)/21), "% - ", IF(INT((COUNTIF(' Capa Integración'!H15:AB15,"Completado")*100)/21)=100,"Completado",IF(INT((COUNTIF(' Capa Integración'!H15:AB15,"Completado")*100)/21)=0,"Pendiente","En Curso"))) -> 100% - Completado | E15: =' Capa Integración'!AC15 -> Completado | F15: =' Capa Integración'!AD15 -> Completado | G15: =' Capa Integración'!AE15 -> Completado | H15: =' Capa Integración'!AF15 -> Pendiente | I15: Endpoints OK + Headers + Logs + SonarQube Pass
B16: =' Capa Integración'!C16 -> sur-auth-ms-mid-identy | C16: Integración | D16: =_xlfn.CONCAT(INT((COUNTIF(' Capa Integración'!H16:AB16,"Completado")*100)/21), "% - ", IF(INT((COUNTIF(' Capa Integración'!H16:AB16,"Completado")*100)/21)=100,"Completado",IF(INT((COUNTIF(' Capa Integración'!H16:AB16,"Completado")*100)/21)=0,"Pendiente","En Curso"))) -> 100% - Completado | E16: =' Capa Integración'!AC16 -> Completado | F16: =' Capa Integración'!AD16 -> Completado | G16: =' Capa Integración'!AE16 -> Completado | H16: =' Capa Integración'!AF16 -> Pendiente | I16: Endpoints OK + Headers + Logs + SonarQube Pass
B17: ='Capa API'!C5 -> sur-auth-authorizers | C17: API | D17: =_xlfn.CONCAT(INT((COUNTIF('Capa API'!H5:AB5,"Completado")*100)/21), "% - ", IF(INT((COUNTIF('Capa API'!H5:AB5,"Completado")*100)/21)=100,"Completado",IF(INT((COUNTIF('Capa API'!H5:AB5,"Completado")*100)/21)=0,"Pendiente","En Curso"))) -> 100% - Completado | E17: ='Capa API'!AC5 -> Completado | F17: ='Capa API'!AD5 -> Completado | G17: ='Capa API'!AE5 -> En Curso | H17: ='Capa API'!AF5 -> Pendiente | I17: Endpoints OK + Headers + Logs + SonarQube Pass
B18: ='Capa API'!C6 -> sur-auth-disbursement | C18: API | D18: =_xlfn.CONCAT(INT((COUNTIF('Capa API'!H6:AB6,"Completado")*100)/21), "% - ", IF(INT((COUNTIF('Capa API'!H6:AB6,"Completado")*100)/21)=100,"Completado",IF(INT((COUNTIF('Capa API'!H6:AB6,"Completado")*100)/21)=0,"Pendiente","En Curso"))) -> 100% - Completado | E18: ='Capa API'!AC6 -> Completado | F18: ='Capa API'!AD6 -> Completado | G18: ='Capa API'!AE6 -> En Curso | H18: ='Capa API'!AF6 -> Pendiente | I18: Endpoints OK + Headers + Logs + SonarQube Pass
B19: ='Capa API'!C7 -> sur-auth-document-generator | C19: API | D19: =_xlfn.CONCAT(INT((COUNTIF('Capa API'!H7:AB7,"Completado")*100)/21), "% - ", IF(INT((COUNTIF('Capa API'!H7:AB7,"Completado")*100)/21)=100,"Completado",IF(INT((COUNTIF('Capa API'!H7:AB7,"Completado")*100)/21)=0,"Pendiente","En Curso"))) -> 100% - Completado | E19: ='Capa API'!AC7 -> Completado | F19: ='Capa API'!AD7 -> En Curso | G19: ='Capa API'!AE7 -> En Curso | H19: ='Capa API'!AF7 -> Pendiente | I19: Endpoints OK + Headers + Logs + SonarQube Pass
B20: ='Capa API'!C8 -> sur-auth-sistematica | C20: API | D20: =_xlfn.CONCAT(INT((COUNTIF('Capa API'!H8:AB8,"Completado")*100)/21), "% - ", IF(INT((COUNTIF('Capa API'!H8:AB8,"Completado")*100)/21)=100,"Completado",IF(INT((COUNTIF('Capa API'!H8:AB8,"Completado")*100)/21)=0,"Pendiente","En Curso"))) -> 100% - Completado | E20: ='Capa API'!AC8 -> Completado | F20: ='Capa API'!AD8 -> Completado | G20: ='Capa API'!AE8 -> En Curso | H20: ='Capa API'!AF8 -> Pendiente | I20: Endpoints OK + Headers + Logs + SonarQube Pass
B21: ='Capa API'!C9 -> sur-auth-grupal | C21: API | D21: =_xlfn.CONCAT(INT((COUNTIF('Capa API'!H9:AB9,"Completado")*100)/21), "% - ", IF(INT((COUNTIF('Capa API'!H9:AB9,"Completado")*100)/21)=100,"Completado",IF(INT((COUNTIF('Capa API'!H9:AB9,"Completado")*100)/21)=0,"Pendiente","En Curso"))) -> 100% - Completado | E21: ='Capa API'!AC9 -> Completado | F21: ='Capa API'!AD9 -> Completado | G21: ='Capa API'!AE9 -> En Curso | H21: ='Capa API'!AF9 -> Pendiente | I21: Endpoints OK + Headers + Logs + SonarQube Pass
B22: ='Capa API'!C10 -> sur-auth-digital-folder | C22: API | D22: =_xlfn.CONCAT(INT((COUNTIF('Capa API'!H10:AB10,"Completado")*100)/21), "% - ", IF(INT((COUNTIF('Capa API'!H10:AB10,"Completado")*100)/21)=100,"Completado",IF(INT((COUNTIF('Capa API'!H10:AB10,"Completado")*100)/21)=0,"Pendiente","En Curso"))) -> 100% - Completado | E22: ='Capa API'!AC10 -> Completado | F22: ='Capa API'!AD10 -> Completado | G22: ='Capa API'!AE10 -> En Curso | H22: ='Capa API'!AF10 -> Pendiente | I22: Endpoints OK + Headers + Logs + SonarQube Pass
B23: ='Capa API'!C11 -> sur-auth-compliance-risk | C23: API | D23: =_xlfn.CONCAT(INT((COUNTIF('Capa API'!H11:AB11,"Completado")*100)/21), "% - ", IF(INT((COUNTIF('Capa API'!H11:AB11,"Completado")*100)/21)=100,"Completado",IF(INT((COUNTIF('Capa API'!H11:AB11,"Completado")*100)/21)=0,"Pendiente","En Curso"))) -> 100% - Completado | E23: ='Capa API'!AC11 -> Completado | F23: ='Capa API'!AD11 -> Completado | G23: ='Capa API'!AE11 -> En Curso | H23: ='Capa API'!AF11 -> Pendiente | I23: Endpoints OK + Headers + Logs + SonarQube Pass
B24: ='Capa API'!C12 -> sur-auth-send-app | C24: API | D24: =_xlfn.CONCAT(INT((COUNTIF('Capa API'!H12:AB12,"Completado")*100)/21), "% - ", IF(INT((COUNTIF('Capa API'!H12:AB12,"Completado")*100)/21)=100,"Completado",IF(INT((COUNTIF('Capa API'!H12:AB12,"Completado")*100)/21)=0,"Pendiente","En Curso"))) -> 100% - Completado | E24: ='Capa API'!AC12 -> Completado | F24: ='Capa API'!AD12 -> Completado | G24: ='Capa API'!AE12 -> En Curso | H24: ='Capa API'!AF12 -> Pendiente | I24: Endpoints OK + Headers + Logs + SonarQube Pass
B25: ='Capa API'!C13 -> sur-auth-workflow | C25: API | D25: =_xlfn.CONCAT(INT((COUNTIF('Capa API'!H13:AB13,"Completado")*100)/21), "% - ", IF(INT((COUNTIF('Capa API'!H13:AB13,"Completado")*100)/21)=100,"Completado",IF(INT((COUNTIF('Capa API'!H13:AB13,"Completado")*100)/21)=0,"Pendiente","En Curso"))) -> 100% - Completado | E25: ='Capa API'!AC13 -> Completado | F25: ='Capa API'!AD13 -> Completado | G25: ='Capa API'!AE13 -> En Curso | H25: ='Capa API'!AF13 -> Pendiente | I25: Endpoints OK + Headers + Logs + SonarQube Pass
B26: ='Capa API'!C14 -> sur-auth-sase-cuma-curema | C26: API | D26: =_xlfn.CONCAT(INT((COUNTIF('Capa API'!H14:AB14,"Completado")*100)/21), "% - ", IF(INT((COUNTIF('Capa API'!H14:AB14,"Completado")*100)/21)=100,"Completado",IF(INT((COUNTIF('Capa API'!H14:AB14,"Completado")*100)/21)=0,"Pendiente","En Curso"))) -> 100% - Completado | E26: ='Capa API'!AC14 -> Completado | F26: ='Capa API'!AD14 -> Completado | G26: ='Capa API'!AE14 -> Completado | H26: ='Capa API'!AF14 -> Pendiente | I26: Endpoints OK + Headers + Logs + SonarQube Pass
B27: ='Capa API'!C15 -> sur-auth-opex-trba-crma | C27: API | D27: =_xlfn.CONCAT(INT((COUNTIF('Capa API'!H15:AB15,"Completado")*100)/21), "% - ", IF(INT((COUNTIF('Capa API'!H15:AB15,"Completado")*100)/21)=100,"Completado",IF(INT((COUNTIF('Capa API'!H15:AB15,"Completado")*100)/21)=0,"Pendiente","En Curso"))) -> 100% - Completado | E27: ='Capa API'!AC15 -> Completado | F27: ='Capa API'!AD15 -> Completado | G27: ='Capa API'!AE15 -> Completado | H27: ='Capa API'!AF15 -> Pendiente | I27: Endpoints OK + Headers + Logs + SonarQube Pass
B28: ='Capa API'!C16 -> sur-auth-msapicustomer | C28: API | D28: =_xlfn.CONCAT(INT((COUNTIF('Capa API'!H16:AB16,"Completado")*100)/21), "% - ", IF(INT((COUNTIF('Capa API'!H16:AB16,"Completado")*100)/21)=100,"Completado",IF(INT((COUNTIF('Capa API'!H16:AB16,"Completado")*100)/21)=0,"Pendiente","En Curso"))) -> 100% - Completado | E28: ='Capa API'!AC16 -> No aplica | F28: ='Capa API'!AD16 -> No aplica | G28: ='Capa API'!AE16 -> No aplica | H28: ='Capa API'!AF16 -> No aplica | I28: Endpoints OK + Headers + Logs + SonarQube Pass
... B32: ='Capa API'!C20 -> sur-auth-web-backend | C32: API | D32: =_xlfn.CONCAT(INT((COUNTIF('Capa API'!H20:AB20,"Completado")*100)/21), "% - ", IF(INT((COUNTIF('Capa API'!H20:AB20,"Completado")*100)/21)=100,"Completado",IF(INT((COUNTIF('Capa API'!H20:AB20,"Completado")*100)/21)=0,"Pendiente","En Curso"))) -> 100% - Completado | E32: ='Capa API'!AC20 -> Completado | F32: ='Capa API'!AD20 -> Completado | G32: ='Capa API'!AE20 -> Completado | H32: ='Capa API'!AF20 -> Pendiente | I32: Endpoints OK + Headers + Logs + SonarQube Pass
B33: ='Capa Orquestación'!C5 -> sur-auth-mstrace | C33: Orquestación | D33: =_xlfn.CONCAT(INT((COUNTIF('Capa Orquestación'!H5:AB5,"Completado")*100)/21), "% - ", IF(INT((COUNTIF('Capa Orquestación'!H5:AB5,"Completado")*100)/21)=100,"Completado",IF(INT((COUNTIF('Capa Orquestación'!H5:AB5,"Completado")*100)/21)=0,"Pendiente","En Curso"))) -> 100% - Completado | E33: ='Capa Orquestación'!AC5 -> Completado | F33: ='Capa Orquestación'!AD5 -> Pendiente | G33: ='Capa Orquestación'!AE5 -> Pendiente | H33: ='Capa Orquestación'!AF5 -> Pendiente | I33: Endpoints OK + Headers + Logs + SonarQube Pass
B34: ='Capa Orquestación'!C6 -> sur-auth-sendonb | C34: Orquestación | D34: =_xlfn.CONCAT(INT((COUNTIF('Capa Orquestación'!H6:AB6,"Completado")*100)/21), "% - ", IF(INT((COUNTIF('Capa Orquestación'!H6:AB6,"Completado")*100)/21)=100,"Completado",IF(INT((COUNTIF('Capa Orquestación'!H6:AB6,"Completado")*100)/21)=0,"Pendiente","En Curso"))) -> 100% - Completado | E34: ='Capa Orquestación'!AC6 -> Completado | F34: ='Capa Orquestación'!AD6 -> Pendiente | G34: ='Capa Orquestación'!AE6 -> Pendiente | H34: ='Capa Orquestación'!AF6 -> Pendiente | I34: Endpoints OK + Headers + Logs + SonarQube Pass
B35: ='Capa Orquestación'!C7 -> sur-auth-rules-evaluation | C35: Orquestación | D35: =_xlfn.CONCAT(INT((COUNTIF('Capa Orquestación'!H7:AB7,"Completado")*100)/21), "% - ", IF(INT((COUNTIF('Capa Orquestación'!H7:AB7,"Completado")*100)/21)=100,"Completado",IF(INT((COUNTIF('Capa Orquestación'!H7:AB7,"Completado")*100)/21)=0,"Pendiente","En Curso"))) -> 100% - Completado | E35: ='Capa Orquestación'!AC7 -> Completado | F35: Completado | G35: ='Capa Orquestación'!AE7 -> Pendiente | H35: ='Capa Orquestación'!AF7 -> Pendiente | I35: Endpoints OK + Headers + Logs + SonarQube Pass
B36: ='Capa Orquestación'!C8 -> sur-auth-broker-functions | C36: Orquestación | D36: =_xlfn.CONCAT(INT((COUNTIF('Capa Orquestación'!H8:AB8,"Completado")*100)/21), "% - ", IF(INT((COUNTIF('Capa Orquestación'!H8:AB8,"Completado")*100)/21)=100,"Completado",IF(INT((COUNTIF('Capa Orquestación'!H8:AB8,"Completado")*100)/21)=0,"Pendiente","En Curso"))) -> 100% - Completado | E36: ='Capa Orquestación'!AC8 -> Completado | F36: ='Capa Orquestación'!AD8 -> Completado | G36: ='Capa Orquestación'!AE8 -> En Curso | H36: ='Capa Orquestación'!AF8 -> Pendiente | I36: Endpoints OK + Headers + Logs + SonarQube Pass
B37: ='Capa Orquestación'!C9 -> sur-auth-fn-system-auth-core-code | C37: Orquestación | D37: =_xlfn.CONCAT(INT((COUNTIF('Capa Orquestación'!H9:AB9,"Completado")*100)/21), "% - ", IF(INT((COUNTIF('Capa Orquestación'!H9:AB9,"Completado")*100)/21)=100,"Completado",IF(INT((COUNTIF('Capa Orquestación'!H9:AB9,"Completado")*100)/21)=0,"Pendiente","En Curso"))) -> 100% - Completado | E37: ='Capa Orquestación'!AC9 -> Completado | F37: ='Capa Orquestación'!AD9 -> Completado | G37: ='Capa Orquestación'!AE9 -> Pendiente | H37: ='Capa Orquestación'!AF9 -> Pendiente | I37: Endpoints OK + Headers + Logs + SonarQube Pass
B38: ='Capa Orquestación'!C10 -> sur-auth-report-workflow | C38: Orquestación | D38: =_xlfn.CONCAT(INT((COUNTIF('Capa Orquestación'!H10:AB10,"Completado")*100)/21), "% - ", IF(INT((COUNTIF('Capa Orquestación'!H10:AB10,"Completado")*100)/21)=100,"Completado",IF(INT((COUNTIF('Capa Orquestación'!H10:AB10,"Completado")*100)/21)=0,"Pendiente","En Curso"))) -> 100% - Completado | E38: ='Capa Orquestación'!AC10 -> Completado | F38: ='Capa Orquestación'!AD10 -> Completado | G38: ='Capa Orquestación'!AE10 -> En Curso | H38: ='Capa Orquestación'!AF10 -> Pendiente | I38: Endpoints OK + Headers + Logs + SonarQube Pass
B39: ='Capa Orquestación'!C11 -> sur-auth-fn-variables-provider | C39: Orquestación | D39: =_xlfn.CONCAT(INT((COUNTIF('Capa Orquestación'!H11:AB11,"Completado")*100)/21), "% - ", IF(INT((COUNTIF('Capa Orquestación'!H11:AB11,"Completado")*100)/21)=100,"Completado",IF(INT((COUNTIF('Capa Orquestación'!H11:AB11,"Completado")*100)/21)=0,"Pendiente","En Curso"))) -> 100% - Completado | E39: ='Capa Orquestación'!AC11 -> Completado | F39: ='Capa Orquestación'!AD11 -> Completado | G39: ='Capa Orquestación'!AE11 -> En Curso | H39: ='Capa Orquestación'!AF11 -> Pendiente | I39: Endpoints OK + Headers + Logs + SonarQube Pass
